Workbook

Sheet README
A1: MVP — PDD + Efeito Vagão + Subordinação (FIDC)
A3: Como usar
A4: 1) Cole/importe a carteira na aba 'INPUT_CARTEIRA' (colunas A–L).
A5: 2) (Opcional) Ajuste parâmetros na aba 'PARAMETROS' (cortes e cotas).
A6: 3) Veja resultados em 'KPIs' e 'SUBORDINACAO'.
A8: Observações
A9: • Dados de devedores/créditos aqui são sintéticos (exemplo), com distribuição realista.
A10: • Fórmulas seguem prática de mercado (régua de atraso + coverage) e adicionam efeito vagão (por devedor).
A11: • Macros e referências públicas estão na aba 'FONTES'.

Sheet PARAMETROS
A1: Parâmetros (inputs)
A3: Corte de inadimplência (dias) p/ indicador | B3: 90
A4: Corte de efeito vagão (dias) p/ gatilho por devedor | B4: 90
A5: Usar efeito vagão? (SIM/NÃO) | B5: NÃO
A6: Cota Sênior (R$) | B6: 1000000
A7: Subordinação mínima (gatilho) % | B7: 0.15
A8: Escopo vagão (TODOS/VINCENDOS) [opcional] | B8: VINCENDOS
A9: (MVP: vagão desligado por padrão)
A10: Observação: ajuste só se quiser simular outra estrutura. O MVP funciona com estes defaults.

Sheet REGUA_PDD
A1: Régua de PDD (exemplo — ajuste conforme regulamento do fundo)
A3: Dias_início (>=) | B3: PDD%
A4: 0 | B4: 0
A5: 1 | B5: 0.1
A6: 31 | B6: 0.3
A7: 61 | B7: 0.5
A8: 91 | B8: 0.7
A9: 181 | B9: 1
A10: Nota: A fórmula usa VLOOKUP aproximado pela coluna Dias_início, então mantenha ordenado crescente.

Sheet INPUT_CARTEIRA
A1: Input — Carteira de Direitos Creditórios (exemplo sintético realista)
A3: Data_base | B3: ID_Crédito | C3: ID_Devedor | D3: Setor | E3: UF | F3: Saldo_bruto | G3: Vencimento | H3: Dias_atraso | I3: Garantia_tipo | J3: Valor_garantia | K3: Haircut_garantia | L3: Evento
A4: 46053 | B4: CR00001 | C4: DEV026 | D4: Saúde | E4: SP | F4: 135173.64 | G4: 46053 | H4: 0 | I4: Sem garantia | J4: 0 | K4: 1
A5: 46053 | B5: CR00002 | C5: DEV021 | D5: Agro | E5: SC | F5: 37065.34 | G5: 46053 | H5: 0 | I5: Sem garantia | J5: 0 | K5: 1
A6: 46053 | B6: CR00003 | C6: DEV002 | D6: Comércio | E6: BA | F6: 49995.69 | G6: 46038 | H6: 15 | I6: Cessão fiduciária | J6: 37570.79 | K6: 0.3
A7: 46053 | B7: CR00004 | C7: DEV008 | D7: Indústria | E7: RS | F7: 62599.32 | G7: 45948 | H7: 105 | I7: Sem garantia | J7: 0 | K7: 1 | L7: Recompra
A8: 46053 | B8: CR00005 | C8: DEV020 | D8: Saúde | E8: PR | F8: 30535.53 | G8: 45725 | H8: 328 | I8: Sem garantia | J8: 0 | K8: 1
A9: 46053 | B9: CR00006 | C9: DEV028 | D9: Saúde | E9: PR | F9: 49081.59 | G9: 46053 | H9: 0 | I9: Reserva de domínio | J9: 53792.65 | K9: 0.3
A10: 46053 | B10: CR00007 | C10: DEV002 | D10: Comércio | E10: BA | F10: 48994.62 | G10: 46053 | H10: 0 | I10: Reserva de domínio | J10: 63146.01 | K10: 0.4 | L10: Renegociação
A11: 46053 | B11: CR00008 | C11: DEV013 | D11: Serviços | E11: CE | F11: 17105.67 | G11: 45974 | H11: 79 | I11: Sem garantia | J11: 0 | K11: 1
A12: 46053 | B12: CR00009 | C12: DEV001 | D12: Indústria | E12: CE | F12: 90273.1 | G12: 45925 | H12: 128 | I12: Cessão fiduciária | J12: 113089.6 | K12: 0.5
A13: 46053 | B13: CR00010 | C13: DEV014 | D13: Serviços | E13: RS | F13: 70283.98 | G13: 46027 | H13: 26 | I13: Cessão fiduciária | J13: 42183.78 | K13: 0.6 | L13: Substituição
A14: 46053 | B14: CR00011 | C14: DEV010 | D14: Serviços | E14: MG | F14: 33682.8 | G14: 46008 | H14: 45 | I14: Alienação fiduciária | J14: 28266.46 | K14: 0.5
A15: 46053 | B15: CR00012 | C15: DEV028 | D15: Saúde | E15: PR | F15: 44226.13 | G15: 45969 | H15: 84 | I15: Sem garantia | J15: 0 | K15: 1
A16: 46053 | B16: CR00013 | C16: DEV002 | D16: Comércio | E16: BA | F16: 66381.89 | G16: 46047 | H16: 6 | I16: Cessão fiduciária | J16: 68534.87 | K16: 0.3
A17: 46053 | B17: CR00014 | C17: DEV018 | D17: Comércio | E17: CE | F17: 41906.08 | G17: 45874 | H17: 179 | I17: Sem garantia | J17: 0 | K17: 1
A18: 46053 | B18: CR00015 | C18: DEV028 | D18: Saúde | E18: PR | F18: 42376.56 | G18: 46053 | H18: 0 | I18: Sem garantia | J18: 0 | K18: 1
A19: 46053 | B19: CR00016 | C19: DEV028 | D19: Saúde | E19: PR | F19: 20497.44 | G19: 46053 | H19: 0 | I19: Sem garantia | J19: 0 | K19: 1
A20: 46053 | B20: CR00017 | C20: DEV004 | D20: Serviços | E20: PR | F20: 68374.02 | G20: 46053 | H20: 0 | I20: Sem garantia | J20: 0 | K20: 1
A21: 46053 | B21: CR00018 | C21: DEV028 | D21: Saúde | E21: PR | F21: 52803.28 | G21: 46053 | H21: 0 | I21: Sem garantia | J21: 0 | K21: 1
A22: 46053 | B22: CR00019 | C22: DEV028 | D22: Saúde | E22: PR | F22: 57796.06 | G22: 45951 | H22: 102 | I22: Sem garantia | J22: 0 | K22: 1
A23: 46053 | B23: CR00020 | C23: DEV014 | D23: Serviços | E23: RS | F23: 19615.69 | G23: 46053 | H23: 0 | I23: Fiança | J23: 15407 | K23: 0.4
A24: 46053 | B24: CR00021 | C24: DEV024 | D24: Serviços | E24: RJ | F24: 131981.87 | G24: 45996 | H24: 57 | I24: Sem garantia | J24: 0 | K24: 1
A25: 46053 | B25: CR00022 | C25: DEV021 | D25: Agro | E25: SC | F25: 53777.01 | G25: 46053 | H25: 0 | I25: Alienação fiduciária | J25: 43839.81 | K25: 0.3 | L25: Recompra
A26: 46053 | B26: CR00023 | C26: DEV024 | D26: Serviços | E26: RJ | F26: 38859.82 | G26: 46053 | H26: 0 | I26: Cessão fiduciária | J26: 23334.7 | K26: 0.3
A27: 46053 | B27: CR00024 | C27: DEV012 | D27: Comércio | E27: RJ | F27: 165618.68 | G27: 46053 | H27: 0 | I27: Cessão fiduciária | J27: 103620.88 | K27: 0.6 | L27: Renegociação
A28: 46053 | B28: CR00025 | C28: DEV017 | D28: Serviços | E28: RJ | F28: 47703.9 | G28: 46053 | H28: 0 | I28: Alienação fiduciária | J28: 34700.49 | K28: 0.3
A29: 46053 | B29: CR00026 | C29: DEV012 | D29: Comércio | E29: RJ | F29: 20528.98 | G29: 46031 | H29: 22 | I29: Sem garantia | J29: 0 | K29: 1
A30: 46053 | B30: CR00027 | C30: DEV023 | D30: Saúde | E30: PE | F30: 38440.36 | G30: 46050 | H30: 3 | I30: Sem garantia | J30: 0 | K30: 1
A31: 46053 | B31: CR00028 | C31: DEV001 | D31: Indústria | E31: CE | F31: 15000 | G31: 46053 | H31: 0 | I31: Alienação fiduciária | J31: 12686.78 | K31: 0.4
A32: 46053 | B32: CR00029 | C32: DEV016 | D32: Agro | E32: MG | F32: 92008.66 | G32: 46006 | H32: 47 | I32: Alienação fiduciária | J32: 81611.68 | K32: 0.3
A33: 46053 | B33: CR00030 | C33: DEV001 | D33: Indústria | E33: CE | F33: 38181.84 | G33: 46053 | H33: 0 | I33: Sem garantia | J33: 0 | K33: 1 | L33: Renegociação
A34: 46053 | B34: CR00031 | C34: DEV011 | D34: Saúde | E34: PE | F34: 31397.01 | G34: 46053 | H34: 0 | I34: Fiança | J34: 23659.13 | K34: 0.6
A35: 46053 | B35: CR00032 | C35: DEV001 | D35: Indústria | E35: CE | F35: 93291.29 | G35: 46053 | H35: 0 | I35: Sem garantia | J35: 0 | K35: 1 | L35: Renegociação
A36: 46053 | B36: CR00033 | C36: DEV028 | D36: Saúde | E36: PR | F36: 18203.24 | G36: 46053 | H36: 0 | I36: Sem garantia | J36: 0 | K36: 1 | L36: Alongamento
A37: 46053 | B37: CR00034 | C37: DEV004 | D37: Serviços | E37: PR | F37: 67592.86 | G37: 45877 | H37: 176 | I37: Sem garantia | J37: 0 | K37: 1
A38: 46053 | B38: CR00035 | C38: DEV020 | D38: Saúde | E38: PR | F38: 15000 | G38: 45921 | H38: 132 | I38: Sem garantia | J38: 0 | K38: 1 | L38: Renegociação
A39: 46053 | B39: CR00036 | C39: DEV002 | D39: Comércio | E39: BA | F39: 32948.61 | G39: 45973 | H39: 80 | I39: Sem garantia | J39: 0 | K39: 1
A40: 46053 | B40: CR00037 | C40: DEV013 | D40: Serviços | E40: CE | F40: 23800.65 | G40: 46053 | H40: 0 | I40: Alienação fiduciária | J40: 29028.77 | K40: 0.4
A41: 46053 | B41: CR00038 | C41: DEV016 | D41: Agro | E41: MG | F41: 117852.06 | G41: 46053 | H41: 0 | I41: Sem garantia | J41: 0 | K41: 1
...

Sheet EFEITO_VAGAO
A1: Efeito Vagão — Sumário por Devedor (gatilho e PDD% mínimo aplicado)
A3: ID_Devedor | B3: Saldo_total | C3: Max_dias_atraso | D3: PDD%_máx_base | E3: Vagão_ativo? | F3: PDD%_mín_devedor
A4: DEV001 | B4: =SUMIF(INPUT_CARTEIRA!$C$4:$C$123,$A4,INPUT_CARTEIRA!$F$4:$F$123) | C4: =MAXIFS(INPUT_CARTEIRA!$H$4:$H$123,INPUT_CARTEIRA!$C$4:$C$123,$A4) | D4: =MAXIFS(CALC_PDD!$N$4:$N$123,CALC_PDD!$C$4:$C$123,$A4) | E4: =$C4>=PARAMETROS!$B$4 | F4: =IF($E4,$D4,0)
A5: DEV002 | B5: =SUMIF(INPUT_CARTEIRA!$C$4:$C$123,$A5,INPUT_CARTEIRA!$F$4:$F$123) | C5: =MAXIFS(INPUT_CARTEIRA!$H$4:$H$123,INPUT_CARTEIRA!$C$4:$C$123,$A5) | D5: =MAXIFS(CALC_PDD!$N$4:$N$123,CALC_PDD!$C$4:$C$123,$A5) | E5: =$C5>=PARAMETROS!$B$4 | F5: =IF($E5,$D5,0)
A6: DEV004 | B6: =SUMIF(INPUT_CARTEIRA!$C$4:$C$123,$A6,INPUT_CARTEIRA!$F$4:$F$123) | C6: =MAXIFS(INPUT_CARTEIRA!$H$4:$H$123,INPUT_CARTEIRA!$C$4:$C$123,$A6) | D6: =MAXIFS(CALC_PDD!$N$4:$N$123,CALC_PDD!$C$4:$C$123,$A6) | E6: =$C6>=PARAMETROS!$B$4 | F6: =IF($E6,$D6,0)
A7: DEV007 | B7: =SUMIF(INPUT_CARTEIRA!$C$4:$C$123,$A7,INPUT_CARTEIRA!$F$4:$F$123) | C7: =MAXIFS(INPUT_CARTEIRA!$H$4:$H$123,INPUT_CARTEIRA!$C$4:$C$123,$A7) | D7: =MAXIFS(CALC_PDD!$N$4:$N$123,CALC_PDD!$C$4:$C$123,$A7) | E7: =$C7>=PARAMETROS!$B$4 | F7: =IF($E7,$D7,0)
A8: DEV008 | B8: =SUMIF(INPUT_CARTEIRA!$C$4:$C$123,$A8,INPUT_CARTEIRA!$F$4:$F$123) | C8: =MAXIFS(INPUT_CARTEIRA!$H$4:$H$123,INPUT_CARTEIRA!$C$4:$C$123,$A8) | D8: =MAXIFS(CALC_PDD!$N$4:$N$123,CALC_PDD!$C$4:$C$123,$A8) | E8: =$C8>=PARAMETROS!$B$4 | F8: =IF($E8,$D8,0)
A9: DEV009 | B9: =SUMIF(INPUT_CARTEIRA!$C$4:$C$123,$A9,INPUT_CARTEIRA!$F$4:$F$123) | C9: =MAXIFS(INPUT_CARTEIRA!$H$4:$H$123,INPUT_CARTEIRA!$C$4:$C$123,$A9) | D9: =MAXIFS(CALC_PDD!$N$4:$N$123,CALC_PDD!$C$4:$C$123,$A9) | E9: =$C9>=PARAMETROS!$B$4 | F9: =IF($E9,$D9,0)
A10: DEV010 | B10: =SUMIF(INPUT_CARTEIRA!$C$4:$C$123,$A10,INPUT_CARTEIRA!$F$4:$F$123) | C10: =MAXIFS(INPUT_CARTEIRA!$H$4:$H$123,INPUT_CARTEIRA!$C$4:$C$123,$A10) | D10: =MAXIFS(CALC_PDD!$N$4:$N$123,CALC_PDD!$C$4:$C$123,$A10) | E10: =$C10>=PARAMETROS!$B$4 | F10: =IF($E10,$D10,0)
A11: DEV011 | B11: =SUMIF(INPUT_CARTEIRA!$C$4:$C$123,$A11,INPUT_CARTEIRA!$F$4:$F$123) | C11: =MAXIFS(INPUT_CARTEIRA!$H$4:$H$123,INPUT_CARTEIRA!$C$4:$C$123,$A11) | D11: =MAXIFS(CALC_PDD!$N$4:$N$123,CALC_PDD!$C$4:$C$123,$A11) | E11: =$C11>=PARAMETROS!$B$4 | F11: =IF($E11,$D11,0)
A12: DEV012 | B12: =SUMIF(INPUT_CARTEIRA!$C$4:$C$123,$A12,INPUT_CARTEIRA!$F$4:$F$123) | C12: =MAXIFS(INPUT_CARTEIRA!$H$4:$H$123,INPUT_CARTEIRA!$C$4:$C$123,$A12) | D12: =MAXIFS(CALC_PDD!$N$4:$N$123,CALC_PDD!$C$4:$C$123,$A12) | E12: =$C12>=PARAMETROS!$B$4 | F12: =IF($E12,$D12,0)
A13: DEV013 | B13: =SUMIF(INPUT_CARTEIRA!$C$4:$C$123,$A13,INPUT_CARTEIRA!$F$4:$F$123) | C13: =MAXIFS(INPUT_CARTEIRA!$H$4:$H$123,INPUT_CARTEIRA!$C$4:$C$123,$A13) | D13: =MAXIFS(CALC_PDD!$N$4:$N$123,CALC_PDD!$C$4:$C$123,$A13) | E13: =$C13>=PARAMETROS!$B$4 | F13: =IF($E13,$D13,0)
A14: DEV014 | B14: =SUMIF(INPUT_CARTEIRA!$C$4:$C$123,$A14,INPUT_CARTEIRA!$F$4:$F$123) | C14: =MAXIFS(INPUT_CARTEIRA!$H$4:$H$123,INPUT_CARTEIRA!$C$4:$C$123,$A14) | D14: =MAXIFS(CALC_PDD!$N$4:$N$123,CALC_PDD!$C$4:$C$123,$A14) | E14: =$C14>=PARAMETROS!$B$4 | F14: =IF($E14,$D14,0)
A15: DEV015 | B15: =SUMIF(INPUT_CARTEIRA!$C$4:$C$123,$A15,INPUT_CARTEIRA!$F$4:$F$123) | C15: =MAXIFS(INPUT_CARTEIRA!$H$4:$H$123,INPUT_CARTEIRA!$C$4:$C$123,$A15) | D15: =MAXIFS(CALC_PDD!$N$4:$N$123,CALC_PDD!$C$4:$C$123,$A15) | E15: =$C15>=PARAMETROS!$B$4 | F15: =IF($E15,$D15,0)
... A27: DEV028 | B27: =SUMIF(INPUT_CARTEIRA!$C$4:$C$123,$A27,INPUT_CARTEIRA!$F$4:$F$123) | C27: =MAXIFS(INPUT_CARTEIRA!$H$4:$H$123,INPUT_CARTEIRA!$C$4:$C$123,$A27) | D27: =MAXIFS(CALC_PDD!$N$4:$N$123,CALC_PDD!$C$4:$C$123,$A27) | E27: =$C27>=PARAMETROS!$B$4 | F27: =IF($E27,$D27,0)

Sheet CALC_PDD
A1: Cálculo — PDD Base + Ajuste por Efeito Vagão (por crédito)
A3: Data_base | B3: ID_Crédito | C3: ID_Devedor | D3: Setor | E3: UF | F3: Saldo_bruto | G3: Vencimento | H3: Dias_atraso | I3: Garantia_tipo | J3: Valor_garantia | K3: Haircut_garantia | L3: Evento | M3: Bucket | N3: PDD%_base | O3: PDD%_devedor(vagão) | P3: PDD%_final | Q3: PDD_valor_final | R3: Inadimplente?(>=corte)
A4: =INPUT_CARTEIRA!A4 | B4: =INPUT_CARTEIRA!B4 | C4: =INPUT_CARTEIRA!C4 | D4: =INPUT_CARTEIRA!D4 | E4: =INPUT_CARTEIRA!E4 | F4: =INPUT_CARTEIRA!F4 | G4: =INPUT_CARTEIRA!G4 | H4: =INPUT_CARTEIRA!H4 | ... L4: =INPUT_CARTEIRA!L4 | M4: =IF($H4=0,"0",IF($H4<=30,"1-30",IF($H4<=60,"31-60",IF($H4<=90,"61-90",IF($H4<=180,"91-180",">180"))))) | N4: =VLOOKUP($H4,REGUA_PDD!$A$4:$B$9,2,TRUE) | O4: =INDEX(EFEITO_VAGAO!$F$4:$F$27, MATCH($C4, EFEITO_VAGAO!$A$4:$A$27, 0)) | P4: =IF(PARAMETROS!$B$5="SIM",MAX($N4,$O4),$N4) | Q4: =$F4*$P4 | R4: =$H4>=PARAMETROS!$B$3
A5: =INPUT_CARTEIRA!A5 | B5: =INPUT_CARTEIRA!B5 | C5: =INPUT_CARTEIRA!C5 | D5: =INPUT_CARTEIRA!D5 | E5: =INPUT_CARTEIRA!E5 | F5: =INPUT_CARTEIRA!F5 | G5: =INPUT_CARTEIRA!G5 | H5: =INPUT_CARTEIRA!H5 | ... L5: =INPUT_CARTEIRA!L5 | M5: =IF($H5=0,"0",IF($H5<=30,"1-30",IF($H5<=60,"31-60",IF($H5<=90,"61-90",IF($H5<=180,"91-180",">180"))))) | N5: =VLOOKUP($H5,REGUA_PDD!$A$4:$B$9,2,TRUE) | O5: =INDEX(EFEITO_VAGAO!$F$4:$F$27, MATCH($C5, EFEITO_VAGAO!$A$4:$A$27, 0)) | P5: =IF(PARAMETROS!$B$5="SIM",MAX($N5,$O5),$N5) | Q5: =$F5*$P5 | R5: =$H5>=PARAMETROS!$B$3
A6: =INPUT_CARTEIRA!A6 | B6: =INPUT_CARTEIRA!B6 | C6: =INPUT_CARTEIRA!C6 | D6: =INPUT_CARTEIRA!D6 | E6: =INPUT_CARTEIRA!E6 | F6: =INPUT_CARTEIRA!F6 | G6: =INPUT_CARTEIRA!G6 | H6: =INPUT_CARTEIRA!H6 | ... L6: =INPUT_CARTEIRA!L6 | M6: =IF($H6=0,"0",IF($H6<=30,"1-30",IF($H6<=60,"31-60",IF($H6<=90,"61-90",IF($H6<=180,"91-180",">180"))))) | N6: =VLOOKUP($H6,REGUA_PDD!$A$4:$B$9,2,TRUE) | O6: =INDEX(EFEITO_VAGAO!$F$4:$F$27, MATCH($C6, EFEITO_VAGAO!$A$4:$A$27, 0)) | P6: =IF(PARAMETROS!$B$5="SIM",MAX($N6,$O6),$N6) | Q6: =$F6*$P6 | R6: =$H6>=PARAMETROS!$B$3
A7: =INPUT_CARTEIRA!A7 | B7: =INPUT_CARTEIRA!B7 | C7: =INPUT_CARTEIRA!C7 | D7: =INPUT_CARTEIRA!D7 | E7: =INPUT_CARTEIRA!E7 | F7: =INPUT_CARTEIRA!F7 | G7: =INPUT_CARTEIRA!G7 | H7: =INPUT_CARTEIRA!H7 | ... L7: =INPUT_CARTEIRA!L7 | M7: =IF($H7=0,"0",IF($H7<=30,"1-30",IF($H7<=60,"31-60",IF($H7<=90,"61-90",IF($H7<=180,"91-180",">180"))))) | N7: =VLOOKUP($H7,REGUA_PDD!$A$4:$B$9,2,TRUE) | O7: =INDEX(EFEITO_VAGAO!$F$4:$F$27, MATCH($C7, EFEITO_VAGAO!$A$4:$A$27, 0)) | P7: =IF(PARAMETROS!$B$5="SIM",MAX($N7,$O7),$N7) | Q7: =$F7*$P7 | R7: =$H7>=PARAMETROS!$B$3
A8: =INPUT_CARTEIRA!A8 | B8: =INPUT_CARTEIRA!B8 | C8: =INPUT_CARTEIRA!C8 | D8: =INPUT_CARTEIRA!D8 | E8: =INPUT_CARTEIRA!E8 | F8: =INPUT_CARTEIRA!F8 | G8: =INPUT_CARTEIRA!G8 | H8: =INPUT_CARTEIRA!H8 | ... L8: =INPUT_CARTEIRA!L8 | M8: =IF($H8=0,"0",IF($H8<=30,"1-30",IF($H8<=60,"31-60",IF($H8<=90,"61-90",IF($H8<=180,"91-180",">180"))))) | N8: =VLOOKUP($H8,REGUA_PDD!$A$4:$B$9,2,TRUE) | O8: =INDEX(EFEITO_VAGAO!$F$4:$F$27, MATCH($C8, EFEITO_VAGAO!$A$4:$A$27, 0)) | P8: =IF(PARAMETROS!$B$5="SIM",MAX($N8,$O8),$N8) | Q8: =$F8*$P8 | R8: =$H8>=PARAMETROS!$B$3
A9: =INPUT_CARTEIRA!A9 | B9: =INPUT_CARTEIRA!B9 | C9: =INPUT_CARTEIRA!C9 | D9: =INPUT_CARTEIRA!D9 | E9: =INPUT_CARTEIRA!E9 | F9: =INPUT_CARTEIRA!F9 | G9: =INPUT_CARTEIRA!G9 | H9: =INPUT_CARTEIRA!H9 | ... L9: =INPUT_CARTEIRA!L9 | M9: =IF($H9=0,"0",IF($H9<=30,"1-30",IF($H9<=60,"31-60",IF($H9<=90,"61-90",IF($H9<=180,"91-180",">180"))))) | N9: =VLOOKUP($H9,REGUA_PDD!$A$4:$B$9,2,TRUE) | O9: =INDEX(EFEITO_VAGAO!$F$4:$F$27, MATCH($C9, EFEITO_VAGAO!$A$4:$A$27, 0)) | P9: =IF(PARAMETROS!$B$5="SIM",MAX($N9,$O9),$N9) | Q9: =$F9*$P9 | R9: =$H9>=PARAMETROS!$B$3
A10: =INPUT_CARTEIRA!A10 | B10: =INPUT_CARTEIRA!B10 | C10: =INPUT_CARTEIRA!C10 | D10: =INPUT_CARTEIRA!D10 | E10: =INPUT_CARTEIRA!E10 | F10: =INPUT_CARTEIRA!F10 | G10: =INPUT_CARTEIRA!G10 | H10: =INPUT_CARTEIRA!H10 | ... L10: =INPUT_CARTEIRA!L10 | M10: =IF($H10=0,"0",IF($H10<=30,"1-30",IF($H10<=60,"31-60",IF($H10<=90,"61-90",IF($H10<=180,"91-180",">180"))))) | N10: =VLOOKUP($H10,REGUA_PDD!$A$4:$B$9,2,TRUE) | O10: =INDEX(EFEITO_VAGAO!$F$4:$F$27, MATCH($C10, EFEITO_VAGAO!$A$4:$A$27, 0)) | P10: =IF(PARAMETROS!$B$5="SIM",MAX($N10,$O10),$N10) | Q10: =$F10*$P10 | R10: =$H10>=PARAMETROS!$B$3
A11: =INPUT_CARTEIRA!A11 | B11: =INPUT_CARTEIRA!B11 | C11: =INPUT_CARTEIRA!C11 | D11: =INPUT_CARTEIRA!D11 | E11: =INPUT_CARTEIRA!E11 | F11: =INPUT_CARTEIRA!F11 | G11: =INPUT_CARTEIRA!G11 | H11: =INPUT_CARTEIRA!H11 | ... L11: =INPUT_CARTEIRA!L11 | M11: =IF($H11=0,"0",IF($H11<=30,"1-30",IF($H11<=60,"31-60",IF($H11<=90,"61-90",IF($H11<=180,"91-180",">180"))))) | N11: =VLOOKUP($H11,REGUA_PDD!$A$4:$B$9,2,TRUE) | O11: =INDEX(EFEITO_VAGAO!$F$4:$F$27, MATCH($C11, EFEITO_VAGAO!$A$4:$A$27, 0)) | P11: =IF(PARAMETROS!$B$5="SIM",MAX($N11,$O11),$N11) | Q11: =$F11*$P11 | R11: =$H11>=PARAMETROS!$B$3
A12: =INPUT_CARTEIRA!A12 | B12: =INPUT_CARTEIRA!B12 | C12: =INPUT_CARTEIRA!C12 | D12: =INPUT_CARTEIRA!D12 | E12: =INPUT_CARTEIRA!E12 | F12: =INPUT_CARTEIRA!F12 | G12: =INPUT_CARTEIRA!G12 | H12: =INPUT_CARTEIRA!H12 | ... L12: =INPUT_CARTEIRA!L12 | M12: =IF($H12=0,"0",IF($H12<=30,"1-30",IF($H12<=60,"31-60",IF($H12<=90,"61-90",IF($H12<=180,"91-180",">180"))))) | N12: =VLOOKUP($H12,REGUA_PDD!$A$4:$B$9,2,TRUE) | O12: =INDEX(EFEITO_VAGAO!$F$4:$F$27, MATCH($C12, EFEITO_VAGAO!$A$4:$A$27, 0)) | P12: =IF(PARAMETROS!$B$5="SIM",MAX($N12,$O12),$N12) | Q12: =$F12*$P12 | R12: =$H12>=PARAMETROS!$B$3
A13: =INPUT_CARTEIRA!A13 | B13: =INPUT_CARTEIRA!B13 | C13: =INPUT_CARTEIRA!C13 | D13: =INPUT_CARTEIRA!D13 | E13: =INPUT_CARTEIRA!E13 | F13: =INPUT_CARTEIRA!F13 | G13: =INPUT_CARTEIRA!G13 | H13: =INPUT_CARTEIRA!H13 | ... L13: =INPUT_CARTEIRA!L13 | M13: =IF($H13=0,"0",IF($H13<=30,"1-30",IF($H13<=60,"31-60",IF($H13<=90,"61-90",IF($H13<=180,"91-180",">180"))))) | N13: =VLOOKUP($H13,REGUA_PDD!$A$4:$B$9,2,TRUE) | O13: =INDEX(EFEITO_VAGAO!$F$4:$F$27, MATCH($C13, EFEITO_VAGAO!$A$4:$A$27, 0)) | P13: =IF(PARAMETROS!$B$5="SIM",MAX($N13,$O13),$N13) | Q13: =$F13*$P13 | R13: =$H13>=PARAMETROS!$B$3
A14: =INPUT_CARTEIRA!A14 | B14: =INPUT_CARTEIRA!B14 | C14: =INPUT_CARTEIRA!C14 | D14: =INPUT_CARTEIRA!D14 | E14: =INPUT_CARTEIRA!E14 | F14: =INPUT_CARTEIRA!F14 | G14: =INPUT_CARTEIRA!G14 | H14: =INPUT_CARTEIRA!H14 | ... L14: =INPUT_CARTEIRA!L14 | M14: =IF($H14=0,"0",IF($H14<=30,"1-30",IF($H14<=60,"31-60",IF($H14<=90,"61-90",IF($H14<=180,"91-180",">180"))))) | N14: =VLOOKUP($H14,REGUA_PDD!$A$4:$B$9,2,TRUE) | O14: =INDEX(EFEITO_VAGAO!$F$4:$F$27, MATCH($C14, EFEITO_VAGAO!$A$4:$A$27, 0)) | P14: =IF(PARAMETROS!$B$5="SIM",MAX($N14,$O14),$N14) | Q14: =$F14*$P14 | R14: =$H14>=PARAMETROS!$B$3
A15: =INPUT_CARTEIRA!A15 | B15: =INPUT_CARTEIRA!B15 | C15: =INPUT_CARTEIRA!C15 | D15: =INPUT_CARTEIRA!D15 | E15: =INPUT_CARTEIRA!E15 | F15: =INPUT_CARTEIRA!F15 | G15: =INPUT_CARTEIRA!G15 | H15: =INPUT_CARTEIRA!H15 | ... L15: =INPUT_CARTEIRA!L15 | M15: =IF($H15=0,"0",IF($H15<=30,"1-30",IF($H15<=60,"31-60",IF($H15<=90,"61-90",IF($H15<=180,"91-180",">180"))))) | N15: =VLOOKUP($H15,REGUA_PDD!$A$4:$B$9,2,TRUE) | O15: =INDEX(EFEITO_VAGAO!$F$4:$F$27, MATCH($C15, EFEITO_VAGAO!$A$4:$A$27, 0)) | P15: =IF(PARAMETROS!$B$5="SIM",MAX($N15,$O15),$N15) | Q15: =$F15*$P15 | R15: =$H15>=PARAMETROS!$B$3
... A123: =INPUT_CARTEIRA!A123 | B123: =INPUT_CARTEIRA!B123 | C123: =INPUT_CARTEIRA!C123 | D123: =INPUT_CARTEIRA!D123 | E123: =INPUT_CARTEIRA!E123 | F123: =INPUT_CARTEIRA!F123 | G123: =INPUT_CARTEIRA!G123 | H123: =INPUT_CARTEIRA!H123 | ... L123: =INPUT_CARTEIRA!L123 | M123: =IF($H123=0,"0",IF($H123<=30,"1-30",IF($H123<=60,"31-60",IF($H123<=90,"61-90",IF($H123<=180,"91-180",">180"))))) | N123: =VLOOKUP($H123,REGUA_PDD!$A$4:$B$9,2,TRUE) | O123: =INDEX(EFEITO_VAGAO!$F$4:$F$27, MATCH($C123, EFEITO_VAGAO!$A$4:$A$27, 0)) | P123: =IF(PARAMETROS!$B$5="SIM",MAX($N123,$O123),$N123) | Q123: =$F123*$P123 | R123: =$H123>=PARAMETROS!$B$3

Sheet KPIs
A1: KPIs — Qualidade de Carteira (PDD, Inadimplência, Coverage)
A3: Carteira total (R$) | B3: =SUM(CALC_PDD!$F$4:$F$123)
A4: PDD total (R$) | B4: =SUM(CALC_PDD!$Q$4:$Q$123)
A5: PDD% (PDD / Carteira) | B5: =IFERROR($B$4/$B$3,0)
A6: Créditos inadimplentes (>=corte) (R$) | B6: =SUMIFS(CALC_PDD!$F$4:$F$123,CALC_PDD!$H$4:$H$123,">="&PARAMETROS!$B$3)
A7: Coverage (PDD / Inadimplentes) | B7: =IFERROR($B$4/$B$6,0)
A9: Distribuição por faixa de atraso (Aging)
A10: Faixa | B10: Saldo (R$) | C10: PDD (R$) | D10: PDD% efetivo
A11: 0 | B11: =SUMIFS(CALC_PDD!$F$4:$F$123,CALC_PDD!$H$4:$H$123,"=0") | C11: =SUMIFS(CALC_PDD!$Q$4:$Q$123,CALC_PDD!$H$4:$H$123,"=0") | D11: =IFERROR($C11/$B11,0)
A12: 1-30 | B12: =SUMIFS(CALC_PDD!$F$4:$F$123,CALC_PDD!$H$4:$H$123,">=1",CALC_PDD!$H$4:$H$123,"<=30") | C12: =SUMIFS(CALC_PDD!$Q$4:$Q$123,CALC_PDD!$H$4:$H$123,">=1",CALC_PDD!$H$4:$H$123,"<=30") | D12: =IFERROR($C12/$B12,0)
A13: 31-60 | B13: =SUMIFS(CALC_PDD!$F$4:$F$123,CALC_PDD!$H$4:$H$123,">=31",CALC_PDD!$H$4:$H$123,"<=60") | C13: =SUMIFS(CALC_PDD!$Q$4:$Q$123,CALC_PDD!$H$4:$H$123,">=31",CALC_PDD!$H$4:$H$123,"<=60") | D13: =IFERROR($C13/$B13,0)
A14: 61-90 | B14: =SUMIFS(CALC_PDD!$F$4:$F$123,CALC_PDD!$H$4:$H$123,">=61",CALC_PDD!$H$4:$H$123,"<=90") | C14: =SUMIFS(CALC_PDD!$Q$4:$Q$123,CALC_PDD!$H$4:$H$123,">=61",CALC_PDD!$H$4:$H$123,"<=90") | D14: =IFERROR($C14/$B14,0)
A15: 91-180 | B15: =SUMIFS(CALC_PDD!$F$4:$F$123,CALC_PDD!$H$4:$H$123,">=91",CALC_PDD!$H$4:$H$123,"<=180") | C15: =SUMIFS(CALC_PDD!$Q$4:$Q$123,CALC_PDD!$H$4:$H$123,">=91",CALC_PDD!$H$4:$H$123,"<=180") | D15: =IFERROR($C15/$B15,0)
A16: >180 | B16: =SUMIFS(CALC_PDD!$F$4:$F$123,CALC_PDD!$H$4:$H$123,">=181") | C16: =SUMIFS(CALC_PDD!$Q$4:$Q$123,CALC_PDD!$H$4:$H$123,">=181") | D16: =IFERROR($C16/$B16,0)
A17: Total | B17: =SUM(B11:B16) | C17: =SUM(C11:C16) | D17: =IFERROR(C17/B17,0)

Sheet SUBORDINACAO
A1: Subordinação — Impacto do PDD no PL e Gatilho
A3: PL bruto (aprox. carteira total) | B3: =KPIs!$B$3
A4: (-) PDD total | B4: =KPIs!$B$4
A5: PL líquido (pós-PDD) | B5: =$B$3-$B$4
A7: Cota Sênior | B7: =PARAMETROS!$B$6
A8: Cota Subordinada (resíduo) | B8: =$B$5-$B$7
A9: Subordinação % (Sub / PL) | B9: =IFERROR($B$8/$B$5,0)
A10: Subordinação mínima | B10: =PARAMETROS!$B$7
A11: Status | B11: =IF($B$9>=$B$10,"ENQUADRADO","DESENQUADRADO") | D11: Obs.: Se Subordinada < 0, a perda já está consumindo a Sênior (modelo simplificado).

Sheet FONTES
A1: Fontes públicas e referências usadas (URLs)
A3: Descrição | B3: URL
A4: ANBIMA — Guia de Metodologia de PDD (Direitos Creditórios) (PDF) | B4: https://www.anbima.com.br/data/files/65/45/BA/DD/73786910FCADB769B82BA2A8/Guia%20ANBIMA%20para%20Metodologia%20de%20PDD%20_Provisao%20de%20Devedores%20Duvidosos_%20de%20Direitos%20Creditorios.pdf
A5: FIDCs.com.br — Indicador PDD (PDD% e Coverage) | B5: https://fidcs.com.br/indicadores-fidc/pdd
A6: BCB Dados Abertos — Taxa de inadimplência PJ (dataset SGS 26203) | B6: https://dadosabertos.bcb.gov.br/dataset/26203-taxa-de-inadimplencia-de-pessoa-juridica---pequeno-porte
A7: Serasa Experian (release empresas inadimplentes, Jan/2026) | B7: https://www.serasaexperian.com.br/sala-de-imprensa/indicadores/novo-recorde-inadimplencia-alcanca-89-milhoes-de-empresas-brasileiras-em-novembro-com-rdollar-210-bilhoes-em-dividas-aponta-serasa-experian/
A8: Serasa — Mapa da Inadimplência (blog; série mensal) | B8: https://www.serasa.com.br/limpa-nome-online/blog/mapa-da-inadimplencia-e-renogociacao-de-dividas-no-brasil/
